{"content": {"suites": {"0": {"status": {"total_pass": 0, "total_skip": 0, "total_xpass": 0, "total_xfail": 0, "total_rerun": 0, "total_fail": 1, "total_error": 0}, "tests": {"0": {"status": "FAIL", "message": "           ConnectionRefusedError: [Errno 61] Connection refused\n       urllib3.exceptions.NewConnectionError: <urllib3.connection.HTTPConnection object at 0x7f99b4545280>: Failed to establish a new connection: [Errno 61] Connection refused\n       urllib3.exceptions.MaxRetryError: HTTPConnectionPool(host='127.0.0.1', port=58320): Max retries exceeded with url: /session/1be32cd26d71caf07863d2a2b869c3c3/url (Caused by NewConnectionError('<urllib3.connection.HTTPConnection object at 0x7f99b4545280>: Failed to establish a new connection: [Errno 61] Connection refused'))\n", "test_name": "test_checkTitle", "rerun": "0"}}, "suite_name": "test_staticPageFooter.py"}}}, "date": "March 10, 2021", "start_time": 1615440871, "total_suite": 1, "status": "FAIL", "status_list": {"pass": "0", "fail": "1", "skip": "0", "error": "0", "xpass": "0", "xfail": "0", "rerun": "0"}, "total_tests": "1"}